{
    "devstack@n-api.service": [],
    "neutron-server": [],
    "devstack@g-api.service": [],
    "null": [],
    "neutron-openvswitch-agent": [],
    "nova-compute": [],
    "nova-scheduler": [],
    "devstack@placement-api.service": [],
    "nova-conductor": [
        " wallacec-ubuntu nova-conductor: ERROR oslo_messaging.rpc.server [None req admin admin] Exception during message handling: DBDataError: (pymysql.err.InternalError) (1366, u\"Incorrect string value: '\\\\xF3\\\\xAD\\\\xA2\\\\xA6&\\\\xF0...' for column 'value' at row 1\") [SQL: u'INSERT INTO instance_system_metadata (created_at, updated_at, deleted_at, deleted, `key`, value, instance_uuid) VALUES (%(created_at)s, %(updated_at)s, %(deleted_at)s, %(deleted)s, %(key)s, %(value)s, %(instance_uuid)s)'] [parameters: {'instance_uuid': u'', 'deleted': 0, 'created_at': datetime.datetime(2019, 1, 25, 23, 6, 41, 827609), 'updated_at': None, 'value': u'\\U000ed8a6&\\U00029878\\x04\\x00', 'key': u'image_min_ram', 'deleted_at': None}] (Background on this error at: http://sqlalche.me/e/2j85)",
        " wallacec-ubuntu nova-conductor: ERROR oslo_messaging.rpc.server Traceback (most recent call last):",
        " wallacec-ubuntu nova-conductor: ERROR oslo_messaging.rpc.server   File \"/usr/local/lib/python2.7/dist-packages/oslo_messaging/rpc/server.py\", line 163, in _process_incoming",
        " wallacec-ubuntu nova-conductor: ERROR oslo_messaging.rpc.server     res = self.dispatcher.dispatch(message)",
        " wallacec-ubuntu nova-conductor: ERROR oslo_messaging.rpc.server   File \"/usr/local/lib/python2.7/dist-packages/oslo_messaging/rpc/dispatcher.py\", line 265, in dispatch",
        " wallacec-ubuntu nova-conductor: ERROR oslo_messaging.rpc.server     return self._do_dispatch(endpoint, method, ctxt, args)",
        " wallacec-ubuntu nova-conductor: ERROR oslo_messaging.rpc.server   File \"/usr/local/lib/python2.7/dist-packages/oslo_messaging/rpc/dispatcher.py\", line 194, in _do_dispatch",
        " wallacec-ubuntu nova-conductor: ERROR oslo_messaging.rpc.server     result = func(ctxt, **new_args)",
        " wallacec-ubuntu nova-conductor: ERROR oslo_messaging.rpc.server   File \"/opt/stack/nova/nova/conductor/manager.py\", line 1303, in schedule_and_build_instances",
        " wallacec-ubuntu nova-conductor: ERROR oslo_messaging.rpc.server     instance.create()",
        " wallacec-ubuntu nova-conductor: ERROR oslo_messaging.rpc.server   File \"/usr/local/lib/python2.7/dist-packages/oslo_versionedobjects/base.py\", line 226, in wrapper",
        " wallacec-ubuntu nova-conductor: ERROR oslo_messaging.rpc.server     return fn(self, *args, **kwargs)",
        " wallacec-ubuntu nova-conductor: ERROR oslo_messaging.rpc.server   File \"/opt/stack/nova/nova/objects/instance.py\", line 600, in create",
        " wallacec-ubuntu nova-conductor: ERROR oslo_messaging.rpc.server     db_inst = db.instance_create(self._context, updates)",
        " wallacec-ubuntu nova-conductor: ERROR oslo_messaging.rpc.server   File \"/opt/stack/nova/nova/db/api.py\", line 748, in instance_create",
        " wallacec-ubuntu nova-conductor: ERROR oslo_messaging.rpc.server     return IMPL.instance_create(context, values)",
        " wallacec-ubuntu nova-conductor: ERROR oslo_messaging.rpc.server   File \"/opt/stack/nova/nova/db/sqlalchemy/api.py\", line 170, in wrapper",
        " wallacec-ubuntu nova-conductor: ERROR oslo_messaging.rpc.server     return f(*args, **kwargs)",
        " wallacec-ubuntu nova-conductor: ERROR oslo_messaging.rpc.server   File \"/usr/local/lib/python2.7/dist-packages/oslo_db/api.py\", line 154, in wrapper",
        " wallacec-ubuntu nova-conductor: ERROR oslo_messaging.rpc.server     ectxt.value = e.inner_exc",
        " wallacec-ubuntu nova-conductor: ERROR oslo_messaging.rpc.server   File \"/usr/local/lib/python2.7/dist-packages/oslo_utils/excutils.py\", line 220, in __exit__",
        " wallacec-ubuntu nova-conductor: ERROR oslo_messaging.rpc.server     self.force_reraise()",
        " wallacec-ubuntu nova-conductor: ERROR oslo_messaging.rpc.server   File \"/usr/local/lib/python2.7/dist-packages/oslo_utils/excutils.py\", line 196, in force_reraise",
        " wallacec-ubuntu nova-conductor: ERROR oslo_messaging.rpc.server     six.reraise(self.type_, self.value, self.tb)",
        " wallacec-ubuntu nova-conductor: ERROR oslo_messaging.rpc.server   File \"/usr/local/lib/python2.7/dist-packages/oslo_db/api.py\", line 142, in wrapper",
        " wallacec-ubuntu nova-conductor: ERROR oslo_messaging.rpc.server     return f(*args, **kwargs)",
        " wallacec-ubuntu nova-conductor: ERROR oslo_messaging.rpc.server   File \"/opt/stack/nova/nova/db/sqlalchemy/api.py\", line 227, in wrapped",
        " wallacec-ubuntu nova-conductor: ERROR oslo_messaging.rpc.server     return f(context, *args, **kwargs)",
        " wallacec-ubuntu nova-conductor: ERROR oslo_messaging.rpc.server   File \"/opt/stack/nova/nova/db/sqlalchemy/api.py\", line 1774, in instance_create",
        " wallacec-ubuntu nova-conductor: ERROR oslo_messaging.rpc.server     ec2_instance_create(context, instance_ref['uuid'])",
        " wallacec-ubuntu nova-conductor: ERROR oslo_messaging.rpc.server   File \"/opt/stack/nova/nova/db/sqlalchemy/api.py\", line 170, in wrapper",
        " wallacec-ubuntu nova-conductor: ERROR oslo_messaging.rpc.server     return f(*args, **kwargs)",
        " wallacec-ubuntu nova-conductor: ERROR oslo_messaging.rpc.server   File \"/opt/stack/nova/nova/db/sqlalchemy/api.py\", line 227, in wrapped",
        " wallacec-ubuntu nova-conductor: ERROR oslo_messaging.rpc.server     return f(context, *args, **kwargs)",
        " wallacec-ubuntu nova-conductor: ERROR oslo_messaging.rpc.server   File \"/opt/stack/nova/nova/db/sqlalchemy/api.py\", line 5286, in ec2_instance_create",
        " wallacec-ubuntu nova-conductor: ERROR oslo_messaging.rpc.server     ec2_instance_ref.save(context.session)",
        " wallacec-ubuntu nova-conductor: ERROR oslo_messaging.rpc.server   File \"/usr/local/lib/python2.7/dist-packages/oslo_db/sqlalchemy/models.py\", line 50, in save",
        " wallacec-ubuntu nova-conductor: ERROR oslo_messaging.rpc.server     session.flush()",
        " wallacec-ubuntu nova-conductor: ERROR oslo_messaging.rpc.server   File \"/usr/local/lib/python2.7/dist-packages/sqlalchemy/orm/session.py\", line 2254, in flush",
        " wallacec-ubuntu nova-conductor: ERROR oslo_messaging.rpc.server     self._flush(objects)",
        " wallacec-ubuntu nova-conductor: ERROR oslo_messaging.rpc.server   File \"/usr/local/lib/python2.7/dist-packages/sqlalchemy/orm/session.py\", line 2380, in _flush",
        " wallacec-ubuntu nova-conductor: ERROR oslo_messaging.rpc.server     transaction.rollback(_capture_exception=True)",
        " wallacec-ubuntu nova-conductor: ERROR oslo_messaging.rpc.server   File \"/usr/local/lib/python2.7/dist-packages/sqlalchemy/util/langhelpers.py\", line 66, in __exit__",
        " wallacec-ubuntu nova-conductor: ERROR oslo_messaging.rpc.server     compat.reraise(exc_type, exc_value, exc_tb)",
        " wallacec-ubuntu nova-conductor: ERROR oslo_messaging.rpc.server   File \"/usr/local/lib/python2.7/dist-packages/sqlalchemy/orm/session.py\", line 2344, in _flush",
        " wallacec-ubuntu nova-conductor: ERROR oslo_messaging.rpc.server     flush_context.execute()",
        " wallacec-ubuntu nova-conductor: ERROR oslo_messaging.rpc.server   File \"/usr/local/lib/python2.7/dist-packages/sqlalchemy/orm/unitofwork.py\", line 391, in execute",
        " wallacec-ubuntu nova-conductor: ERROR oslo_messaging.rpc.server     rec.execute(self)",
        " wallacec-ubuntu nova-conductor: ERROR oslo_messaging.rpc.server   File \"/usr/local/lib/python2.7/dist-packages/sqlalchemy/orm/unitofwork.py\", line 556, in execute",
        " wallacec-ubuntu nova-conductor: ERROR oslo_messaging.rpc.server     uow",
        " wallacec-ubuntu nova-conductor: ERROR oslo_messaging.rpc.server   File \"/usr/local/lib/python2.7/dist-packages/sqlalchemy/orm/persistence.py\", line 181, in save_obj",
        " wallacec-ubuntu nova-conductor: ERROR oslo_messaging.rpc.server     mapper, table, insert)",
        " wallacec-ubuntu nova-conductor: ERROR oslo_messaging.rpc.server   File \"/usr/local/lib/python2.7/dist-packages/sqlalchemy/orm/persistence.py\", line 866, in _emit_insert_statements",
        " wallacec-ubuntu nova-conductor: ERROR oslo_messaging.rpc.server     execute(statement, params)",
        " wallacec-ubuntu nova-conductor: ERROR oslo_messaging.rpc.server   File \"/usr/local/lib/python2.7/dist-packages/sqlalchemy/engine/base.py\", line 948, in execute",
        " wallacec-ubuntu nova-conductor: ERROR oslo_messaging.rpc.server     return meth(self, multiparams, params)",
        " wallacec-ubuntu nova-conductor: ERROR oslo_messaging.rpc.server   File \"/usr/local/lib/python2.7/dist-packages/sqlalchemy/sql/elements.py\", line 269, in _execute_on_connection",
        " wallacec-ubuntu nova-conductor: ERROR oslo_messaging.rpc.server     return connection._execute_clauseelement(self, multiparams, params)",
        " wallacec-ubuntu nova-conductor: ERROR oslo_messaging.rpc.server   File \"/usr/local/lib/python2.7/dist-packages/sqlalchemy/engine/base.py\", line 1060, in _execute_clauseelement",
        " wallacec-ubuntu nova-conductor: ERROR oslo_messaging.rpc.server     compiled_sql, distilled_params",
        " wallacec-ubuntu nova-conductor: ERROR oslo_messaging.rpc.server   File \"/usr/local/lib/python2.7/dist-packages/sqlalchemy/engine/base.py\", line 1200, in _execute_context",
        " wallacec-ubuntu nova-conductor: ERROR oslo_messaging.rpc.server     context)",
        " wallacec-ubuntu nova-conductor: ERROR oslo_messaging.rpc.server   File \"/usr/local/lib/python2.7/dist-packages/sqlalchemy/engine/base.py\", line 1409, in _handle_dbapi_exception",
        " wallacec-ubuntu nova-conductor: ERROR oslo_messaging.rpc.server     util.raise_from_cause(newraise, exc_info)",
        " wallacec-ubuntu nova-conductor: ERROR oslo_messaging.rpc.server   File \"/usr/local/lib/python2.7/dist-packages/sqlalchemy/util/compat.py\", line 265, in raise_from_cause",
        " wallacec-ubuntu nova-conductor: ERROR oslo_messaging.rpc.server     reraise(type(exception), exception, tb=exc_tb, cause=cause)",
        " wallacec-ubuntu nova-conductor: ERROR oslo_messaging.rpc.server   File \"/usr/local/lib/python2.7/dist-packages/sqlalchemy/engine/base.py\", line 1193, in _execute_context",
        " wallacec-ubuntu nova-conductor: ERROR oslo_messaging.rpc.server     context)",
        " wallacec-ubuntu nova-conductor: ERROR oslo_messaging.rpc.server   File \"/usr/local/lib/python2.7/dist-packages/sqlalchemy/engine/default.py\", line 509, in do_execute",
        " wallacec-ubuntu nova-conductor: ERROR oslo_messaging.rpc.server     cursor.execute(statement, parameters)",
        " wallacec-ubuntu nova-conductor: ERROR oslo_messaging.rpc.server   File \"/usr/local/lib/python2.7/dist-packages/pymysql/cursors.py\", line 170, in execute",
        " wallacec-ubuntu nova-conductor: ERROR oslo_messaging.rpc.server     result = self._query(query)",
        " wallacec-ubuntu nova-conductor: ERROR oslo_messaging.rpc.server   File \"/usr/local/lib/python2.7/dist-packages/pymysql/cursors.py\", line 328, in _query",
        " wallacec-ubuntu nova-conductor: ERROR oslo_messaging.rpc.server     conn.query(q)",
        " wallacec-ubuntu nova-conductor: ERROR oslo_messaging.rpc.server   File \"/usr/local/lib/python2.7/dist-packages/pymysql/connections.py\", line 516, in query",
        " wallacec-ubuntu nova-conductor: ERROR oslo_messaging.rpc.server     self._affected_rows = self._read_query_result(unbuffered=unbuffered)",
        " wallacec-ubuntu nova-conductor: ERROR oslo_messaging.rpc.server   File \"/usr/local/lib/python2.7/dist-packages/pymysql/connections.py\", line 727, in _read_query_result",
        " wallacec-ubuntu nova-conductor: ERROR oslo_messaging.rpc.server     result.read()",
        " wallacec-ubuntu nova-conductor: ERROR oslo_messaging.rpc.server   File \"/usr/local/lib/python2.7/dist-packages/pymysql/connections.py\", line 1066, in read",
        " wallacec-ubuntu nova-conductor: ERROR oslo_messaging.rpc.server     first_packet = self.connection._read_packet()",
        " wallacec-ubuntu nova-conductor: ERROR oslo_messaging.rpc.server   File \"/usr/local/lib/python2.7/dist-packages/pymysql/connections.py\", line 683, in _read_packet",
        " wallacec-ubuntu nova-conductor: ERROR oslo_messaging.rpc.server     packet.check_error()",
        " wallacec-ubuntu nova-conductor: ERROR oslo_messaging.rpc.server   File \"/usr/local/lib/python2.7/dist-packages/pymysql/protocol.py\", line 220, in check_error",
        " wallacec-ubuntu nova-conductor: ERROR oslo_messaging.rpc.server     err.raise_mysql_exception(self._data)",
        " wallacec-ubuntu nova-conductor: ERROR oslo_messaging.rpc.server   File \"/usr/local/lib/python2.7/dist-packages/pymysql/err.py\", line 109, in raise_mysql_exception",
        " wallacec-ubuntu nova-conductor: ERROR oslo_messaging.rpc.server     raise errorclass(errno, errval)",
        " wallacec-ubuntu nova-conductor: ERROR oslo_messaging.rpc.server DBDataError: (pymysql.err.InternalError) (1366, u\"Incorrect string value: '\\\\xF3\\\\xAD\\\\xA2\\\\xA6&\\\\xF0...' for column 'value' at row 1\") [SQL: u'INSERT INTO instance_system_metadata (created_at, updated_at, deleted_at, deleted, `key`, value, instance_uuid) VALUES (%(created_at)s, %(updated_at)s, %(deleted_at)s, %(deleted)s, %(key)s, %(value)s, %(instance_uuid)s)'] [parameters: {'instance_uuid': u'', 'deleted': 0, 'created_at': datetime.datetime(2019, 1, 25, 23, 6, 41, 827609), 'updated_at': None, 'value': u'\\U000ed8a6&\\U00029878\\x04\\x00', 'key': u'image_min_ram', 'deleted_at': None}] (Background on this error at: http://sqlalche.me/e/2j85)",
        " wallacec-ubuntu nova-conductor: ERROR oslo_messaging.rpc.server "
    ],
    "devstack@keystone.service": [],
    "neutron-dhcp-agent": [],
    "neutron-l3-agent": [],
    "cinder-volume": [],
    "cinder-scheduler": [],
    "tester": [
        "ERROR     __main__                  run_error_injection_round  192: ",
        "Traceback (most recent call last):",
        "  File \"osdsn2/experiment.py\", line 190, in run_error_injection_round",
        "    self._default_program.run_inputs()",
        "  File \"/media/wallacec/SAMSUNG-500/LINUX/development/javadocto/osdsn2/osdsn2/program.py\", line 115, in run_inputs",
        "    self._program_driver.run_input(inp)",
        "  File \"/media/wallacec/SAMSUNG-500/LINUX/development/javadocto/osdsn2/osdsn2/driver.py\", line 75, in run_input",
        "    self.wait_for_inp(inp, expect_exception='deleted' in [w.lower() for w in inp.waits])",
        "  File \"/media/wallacec/SAMSUNG-500/LINUX/development/javadocto/osdsn2/osdsn2/driver.py\", line 156, in wait_for_inp",
        "    raise e",
        "  File \"/media/wallacec/SAMSUNG-500/LINUX/development/javadocto/osdsn2/osdsn2/driver.py\", line 146, in wait_for_inp",
        "    update_callback=lambda: getattr(self._compute_client.servers.get(self._server_running),",
        "  File \"/media/wallacec/SAMSUNG-500/LINUX/development/javadocto/osdsn2/osdsn2/driver.py\", line 132, in wait_until",
        "    raise TimeoutError()",
        "TimeoutError"
    ]
}